[2025-02-14T18:34:27.823+0000] {local_task_job_runner.py:123} INFO - ::group::Pre task execution logs
[2025-02-14T18:34:27.834+0000] {taskinstance.py:2613} INFO - Dependencies all met for dep_context=non-requeueable deps ti=<TaskInstance: web_to_snowflake.transform_sec_data manual__2025-02-14T18:31:55.208523+00:00 [queued]>
[2025-02-14T18:34:27.840+0000] {taskinstance.py:2613} INFO - Dependencies all met for dep_context=requeueable deps ti=<TaskInstance: web_to_snowflake.transform_sec_data manual__2025-02-14T18:31:55.208523+00:00 [queued]>
[2025-02-14T18:34:27.840+0000] {taskinstance.py:2866} INFO - Starting attempt 1 of 1
[2025-02-14T18:34:27.850+0000] {taskinstance.py:2889} INFO - Executing <Task(PythonOperator): transform_sec_data> on 2025-02-14 18:31:55.208523+00:00
[2025-02-14T18:34:27.865+0000] {warnings.py:112} WARNING - /home/***/.local/lib/python3.12/site-packages/***/task/task_runner/standard_task_runner.py:70: DeprecationWarning: This process (pid=3508) is multi-threaded, use of fork() may lead to deadlocks in the child.
  pid = os.fork()

[2025-02-14T18:34:27.867+0000] {standard_task_runner.py:72} INFO - Started process 3509 to run task
[2025-02-14T18:34:27.867+0000] {standard_task_runner.py:104} INFO - Running: ['***', 'tasks', 'run', 'web_to_snowflake', 'transform_sec_data', 'manual__2025-02-14T18:31:55.208523+00:00', '--job-id', '226', '--raw', '--subdir', 'DAGS_FOLDER/web_to_snowflake.py', '--cfg-path', '/tmp/tmpr0wavd8z']
[2025-02-14T18:34:27.871+0000] {standard_task_runner.py:105} INFO - Job 226: Subtask transform_sec_data
[2025-02-14T18:34:27.938+0000] {task_command.py:467} INFO - Running <TaskInstance: web_to_snowflake.transform_sec_data manual__2025-02-14T18:31:55.208523+00:00 [running]> on host 715f5b9093d1
[2025-02-14T18:34:28.001+0000] {taskinstance.py:3132} INFO - Exporting env vars: AIRFLOW_CTX_DAG_OWNER='***' AIRFLOW_CTX_DAG_ID='web_to_snowflake' AIRFLOW_CTX_TASK_ID='transform_sec_data' AIRFLOW_CTX_EXECUTION_DATE='2025-02-14T18:31:55.208523+00:00' AIRFLOW_CTX_TRY_NUMBER='1' AIRFLOW_CTX_DAG_RUN_ID='manual__2025-02-14T18:31:55.208523+00:00'
[2025-02-14T18:34:28.003+0000] {taskinstance.py:731} INFO - ::endgroup::
[2025-02-14T18:34:28.018+0000] {taskinstance.py:3311} ERROR - Task failed with exception
Traceback (most recent call last):
  File "/home/airflow/.local/lib/python3.12/site-packages/airflow/models/taskinstance.py", line 767, in _execute_task
    result = _execute_callable(context=context, **execute_callable_kwargs)
             ^^^^^^^^^^^^^^^^^^^^^^^^^^^^^^^^^^^^^^^^^^^^^^^^^^^^^^^^^^^^^
  File "/home/airflow/.local/lib/python3.12/site-packages/airflow/models/taskinstance.py", line 733, in _execute_callable
    return ExecutionCallableRunner(
           ^^^^^^^^^^^^^^^^^^^^^^^^
  File "/home/airflow/.local/lib/python3.12/site-packages/airflow/utils/operator_helpers.py", line 252, in run
    return self.func(*args, **kwargs)
           ^^^^^^^^^^^^^^^^^^^^^^^^^^
  File "/home/airflow/.local/lib/python3.12/site-packages/airflow/models/baseoperator.py", line 422, in wrapper
    return func(self, *args, **kwargs)
           ^^^^^^^^^^^^^^^^^^^^^^^^^^^
  File "/home/airflow/.local/lib/python3.12/site-packages/airflow/operators/python.py", line 238, in execute
    return_value = self.execute_callable()
                   ^^^^^^^^^^^^^^^^^^^^^^^
  File "/home/airflow/.local/lib/python3.12/site-packages/airflow/operators/python.py", line 256, in execute_callable
    return runner.run(*self.op_args, **self.op_kwargs)
           ^^^^^^^^^^^^^^^^^^^^^^^^^^^^^^^^^^^^^^^^^^^
  File "/home/airflow/.local/lib/python3.12/site-packages/airflow/utils/operator_helpers.py", line 252, in run
    return self.func(*args, **kwargs)
           ^^^^^^^^^^^^^^^^^^^^^^^^^^
TypeError: process_file() missing 1 required positional argument: 's3_key'
[2025-02-14T18:34:28.026+0000] {taskinstance.py:1225} INFO - Marking task as FAILED. dag_id=web_to_snowflake, task_id=transform_sec_data, run_id=manual__2025-02-14T18:31:55.208523+00:00, execution_date=20250214T183155, start_date=20250214T183427, end_date=20250214T183428
[2025-02-14T18:34:28.034+0000] {taskinstance.py:340} INFO - ::group::Post task execution logs
[2025-02-14T18:34:28.034+0000] {standard_task_runner.py:124} ERROR - Failed to execute job 226 for task transform_sec_data (process_file() missing 1 required positional argument: 's3_key'; 3509)
Traceback (most recent call last):
  File "/home/airflow/.local/lib/python3.12/site-packages/airflow/task/task_runner/standard_task_runner.py", line 117, in _start_by_fork
    ret = args.func(args, dag=self.dag)
          ^^^^^^^^^^^^^^^^^^^^^^^^^^^^^
  File "/home/airflow/.local/lib/python3.12/site-packages/airflow/cli/cli_config.py", line 49, in command
    return func(*args, **kwargs)
           ^^^^^^^^^^^^^^^^^^^^^
  File "/home/airflow/.local/lib/python3.12/site-packages/airflow/utils/cli.py", line 116, in wrapper
    return f(*args, **kwargs)
           ^^^^^^^^^^^^^^^^^^
  File "/home/airflow/.local/lib/python3.12/site-packages/airflow/cli/commands/task_command.py", line 483, in task_run
    task_return_code = _run_task_by_selected_method(args, _dag, ti)
                       ^^^^^^^^^^^^^^^^^^^^^^^^^^^^^^^^^^^^^^^^^^^^
  File "/home/airflow/.local/lib/python3.12/site-packages/airflow/cli/commands/task_command.py", line 256, in _run_task_by_selected_method
    return _run_raw_task(args, ti)
           ^^^^^^^^^^^^^^^^^^^^^^^
  File "/home/airflow/.local/lib/python3.12/site-packages/airflow/cli/commands/task_command.py", line 341, in _run_raw_task
    return ti._run_raw_task(
           ^^^^^^^^^^^^^^^^^
  File "/home/airflow/.local/lib/python3.12/site-packages/airflow/utils/session.py", line 97, in wrapper
    return func(*args, session=session, **kwargs)
           ^^^^^^^^^^^^^^^^^^^^^^^^^^^^^^^^^^^^^^
  File "/home/airflow/.local/lib/python3.12/site-packages/airflow/models/taskinstance.py", line 3005, in _run_raw_task
    return _run_raw_task(
           ^^^^^^^^^^^^^^
  File "/home/airflow/.local/lib/python3.12/site-packages/airflow/models/taskinstance.py", line 273, in _run_raw_task
    TaskInstance._execute_task_with_callbacks(
  File "/home/airflow/.local/lib/python3.12/site-packages/airflow/models/taskinstance.py", line 3159, in _execute_task_with_callbacks
    result = self._execute_task(context, task_orig)
             ^^^^^^^^^^^^^^^^^^^^^^^^^^^^^^^^^^^^^^
  File "/home/airflow/.local/lib/python3.12/site-packages/airflow/models/taskinstance.py", line 3183, in _execute_task
    return _execute_task(self, context, task_orig)
           ^^^^^^^^^^^^^^^^^^^^^^^^^^^^^^^^^^^^^^^
  File "/home/airflow/.local/lib/python3.12/site-packages/airflow/models/taskinstance.py", line 767, in _execute_task
    result = _execute_callable(context=context, **execute_callable_kwargs)
             ^^^^^^^^^^^^^^^^^^^^^^^^^^^^^^^^^^^^^^^^^^^^^^^^^^^^^^^^^^^^^
  File "/home/airflow/.local/lib/python3.12/site-packages/airflow/models/taskinstance.py", line 733, in _execute_callable
    return ExecutionCallableRunner(
           ^^^^^^^^^^^^^^^^^^^^^^^^
  File "/home/airflow/.local/lib/python3.12/site-packages/airflow/utils/operator_helpers.py", line 252, in run
    return self.func(*args, **kwargs)
           ^^^^^^^^^^^^^^^^^^^^^^^^^^
  File "/home/airflow/.local/lib/python3.12/site-packages/airflow/models/baseoperator.py", line 422, in wrapper
    return func(self, *args, **kwargs)
           ^^^^^^^^^^^^^^^^^^^^^^^^^^^
  File "/home/airflow/.local/lib/python3.12/site-packages/airflow/operators/python.py", line 238, in execute
    return_value = self.execute_callable()
                   ^^^^^^^^^^^^^^^^^^^^^^^
  File "/home/airflow/.local/lib/python3.12/site-packages/airflow/operators/python.py", line 256, in execute_callable
    return runner.run(*self.op_args, **self.op_kwargs)
           ^^^^^^^^^^^^^^^^^^^^^^^^^^^^^^^^^^^^^^^^^^^
  File "/home/airflow/.local/lib/python3.12/site-packages/airflow/utils/operator_helpers.py", line 252, in run
    return self.func(*args, **kwargs)
           ^^^^^^^^^^^^^^^^^^^^^^^^^^
TypeError: process_file() missing 1 required positional argument: 's3_key'
[2025-02-14T18:34:28.049+0000] {local_task_job_runner.py:266} INFO - Task exited with return code 1
[2025-02-14T18:34:28.071+0000] {taskinstance.py:3895} INFO - 0 downstream tasks scheduled from follow-on schedule check
[2025-02-14T18:34:28.074+0000] {local_task_job_runner.py:245} INFO - ::endgroup::
